Workbook

Sheet Read me
A1: CRYPTO ANALYSIS V6
A3: Version 7 — 8 October 2026 (file: Crypto Analysis V7). 38 coins; data as of 2026-10-07 (see Last evaluated per coin).
A4: What it is: a score and a tier for each coin from fifteen retrieved facts. No buy or sell calls. An analytical framework, not financial advice; ratings do not predict price.
A5: Sheets: Grades (the live scorer: enter grades here) | Schedule (when each coin is due for reassessment, and the 52-week calendar) | Evidence (value | source | date behind every grade) | Coin notes (what it does, biggest risk, open point) | Usage method (line 6 workings) | Decisions (every ruling made) | Change log (every change, newest first) | Settings (points, cut-offs, group rules, tiers, basket).
A6: Colors: blue text on yellow = you enter it. Black = calculated.
A7: Rules and steps: Crypto Analysis Method V7.md. Summary: crypto_analysis_summary.py. Coin report: crypto_analysis_report.py. Binder snapshot: crypto_portfolio_snapshot.py. Review schedule: crypto_review_schedule.py.
A8: Check after any change: Group check column shows OK for every coin, and no cell shows an error.
A10: VERSION LOG (newest first)
A11: V7 Review schedule: new Schedule tab. Coins I hold are reassessed every 13 weeks and every other coin every 26 weeks, spread so about two come due each week; a calendar file gives a Monday list. New coins and changes in holdings are placed automatically by crypto_review_schedule.py. Major: new tab; no grade, score or tier changed.
A12: V6.1 GRASS added (38 coins) from Lean_Scoring_Workbook_V5_2_2026-10-07_GRASS and Lean_Evidence_Table_2026-10-07_GRASS: grades, evidence, coin notes, decisions and change log. ETH Last evaluated corrected to 2026-10-07. Minor: a coin added.
A13: V6 Restructure: the Lean V5.2 scoring workbook and evidence table merged into one file; all 15 grades entered on one sheet (Grades); legacy 10-line sheets and columns removed; CoinGecko IDs and Last evaluated added as columns; one change log; one decisions list; four contradictory notes corrected. No grade, score or tier changed. Major: new structure.
A14: V5.2 and earlier: see Change log and Decisions (Lean V5.2 history).

Sheet Grades
A1: GRADES: one row per coin. Enter the group, cap and the 15 grades (A–E, NA, or blank) in the yellow cells; everything else is calculated.
A2: Blank = not retrieved (not scored, lowers coverage). NA = not applicable (removed from the denominator). Score = earned ÷ scored × 100. Below 70% coverage no tier is printed.
H3: Points → | I3: =Settings!$C$12 -> 10 | J3: =Settings!$C$13 -> 5 | K3: =Settings!$C$14 -> 5 | L3: =Settings!$C$15 -> 5 | M3: =Settings!$C$16 -> 10 | N3: =Settings!$C$17 -> 10 | O3: =Settings!$C$18 -> 5 | P3: =Settings!$C$19 -> 5 | Q3: =Settings!$C$20 -> 10 | R3: =Settings!$C$21 -> 5 | S3: =Settings!$C$22 -> 10 | T3: =Settings!$C$23 -> 5 | U3: =Settings!$C$24 -> 5 | V3: =Settings!$C$25 -> 5 | W3: =Settings!$C$26 -> 5
A4: Ticker | B4: Name | C4: Group | D4: Score | E4: Rating (/10) | F4: Coverage | G4: Tier | H4: Cap (3 or 4) | I4: L1 | J4: L2 | K4: L3 | L4: L4 | M4: L5 | N4: L6 | O4: L7 | P4: L8 | Q4: L9 | R4: L10 | S4: L11 | T4: L12 | U4: L13 | V4: L14 | W4: L15 | X4: Last evaluated | Y4: CoinGecko ID | Z4: Applicable | AA4: Scored | AB4: Earned | AC4: Score tier # | AD4: Final tier # | AE4: Group check
A5: BTC | B5: Bitcoin | C5: Money coin | D5: =IF(AA5=0,"",ROUND(AB5/AA5*100,1)) -> 90.3 | E5: =IF(D5="","",ROUND(D5/10,1)) -> 9 | F5: =IF(Z5=0,0,AA5/Z5) -> 1 | G5: =IF(D5="","",IF(F5<Settings!$B$42,"Not rated (low coverage)",CHOOSE(AD5,"Exceptional","Strong","Average/Decent","Weak"))) -> Exceptional | I5: A | J5: A | K5: A | L5: NA | M5: A | N5: C | O5: C | P5: A | Q5: A | R5: A | S5: A | T5: NA | U5: A | V5: A | W5: B | X5: 2026-10-05 | Y5: bitcoin | Z5: =SUMPRODUCT(--(I5:W5<>"NA"),I$3:W$3) -> 90 | AA5: =SUMPRODUCT(--(I5:W5<>""),--(I5:W5<>"NA"),I$3:W$3) -> 90 | AB5: =SUMPRODUCT((I5:W5="A")*Settings!$B$4+(I5:W5="B")*Settings!$B$5+(I5:W5="C")*Settings!$B$6+(I5:W5="D")*Settings!$B$7+(I5:W5="E")*Settings!$B$8,I$3:W$3) -> 81.25 | AC5: =IF(D5="","",IF(D5>=Settings!$B$39,1,IF(D5>=Settings!$B$40,2,IF(D5>=Settings!$B$41,3,4)))) -> 1 | AD5: =IF(AC5="","",IF(H5="",IF(C5="Memecoin",MAX(AC5,3),AC5),IF(H5>=4,MAX(AC5,H5),IF(C5="Memecoin",MAX(AC5,3),MAX(AC5,MIN(H5,AC5+1)))))) -> 1 | AE5: =IF(C5="","",IF(SUMPRODUCT((INDEX(Settings!$B$31:$P$34,MATCH(C5,Settings!$A$31:$A$34,0),0)=1)*(I5:W5<>"NA"))>0,"Group NA missing","OK")) -> OK
A6: ETH | B6: Ethereum | C6: Chain / protocol | D6: =IF(AA6=0,"",ROUND(AB6/AA6*100,1)) -> 86.3 | E6: =IF(D6="","",ROUND(D6/10,1)) -> 8.6 | F6: =IF(Z6=0,0,AA6/Z6) -> 1 | G6: =IF(D6="","",IF(F6<Settings!$B$42,"Not rated (low coverage)",CHOOSE(AD6,"Exceptional","Strong","Average/Decent","Weak"))) -> Strong | I6: A | J6: A | K6: A | L6: B | M6: A | N6: D | O6: C | P6: A | Q6: A | R6: A | S6: A | T6: C | U6: A | V6: A | W6: A | X6: 2026-10-07 | Y6: ethereum | Z6: =SUMPRODUCT(--(I6:W6<>"NA"),I$3:W$3) -> 100 | AA6: =SUMPRODUCT(--(I6:W6<>""),--(I6:W6<>"NA"),I$3:W$3) -> 100 | AB6: =SUMPRODUCT((I6:W6="A")*Settings!$B$4+(I6:W6="B")*Settings!$B$5+(I6:W6="C")*Settings!$B$6+(I6:W6="D")*Settings!$B$7+(I6:W6="E")*Settings!$B$8,I$3:W$3) -> 86.25 | AC6: =IF(D6="","",IF(D6>=Settings!$B$39,1,IF(D6>=Settings!$B$40,2,IF(D6>=Settings!$B$41,3,4)))) -> 2 | AD6: =IF(AC6="","",IF(H6="",IF(C6="Memecoin",MAX(AC6,3),AC6),IF(H6>=4,MAX(AC6,H6),IF(C6="Memecoin",MAX(AC6,3),MAX(AC6,MIN(H6,AC6+1)))))) -> 2 | AE6: =IF(C6="","",IF(SUMPRODUCT((INDEX(Settings!$B$31:$P$34,MATCH(C6,Settings!$A$31:$A$34,0),0)=1)*(I6:W6<>"NA"))>0,"Group NA missing","OK")) -> OK
A7: SOL | B7: Solana | C7: Chain / protocol | D7: =IF(AA7=0,"",ROUND(AB7/AA7*100,1)) -> 80 | E7: =IF(D7="","",ROUND(D7/10,1)) -> 8 | F7: =IF(Z7=0,0,AA7/Z7) -> 1 | G7: =IF(D7="","",IF(F7<Settings!$B$42,"Not rated (low coverage)",CHOOSE(AD7,"Exceptional","Strong","Average/Decent","Weak"))) -> Strong | I7: A | J7: B | K7: D | L7: C | M7: A | N7: D | O7: B | P7: A | Q7: B | R7: A | S7: A | T7: A | U7: A | V7: B | W7: A | X7: 2026-10-05 | Y7: solana | Z7: =SUMPRODUCT(--(I7:W7<>"NA"),I$3:W$3) -> 100 | AA7: =SUMPRODUCT(--(I7:W7<>""),--(I7:W7<>"NA"),I$3:W$3) -> 100 | AB7: =SUMPRODUCT((I7:W7="A")*Settings!$B$4+(I7:W7="B")*Settings!$B$5+(I7:W7="C")*Settings!$B$6+(I7:W7="D")*Settings!$B$7+(I7:W7="E")*Settings!$B$8,I$3:W$3) -> 80 | AC7: =IF(D7="","",IF(D7>=Settings!$B$39,1,IF(D7>=Settings!$B$40,2,IF(D7>=Settings!$B$41,3,4)))) -> 2 | AD7: =IF(AC7="","",IF(H7="",IF(C7="Memecoin",MAX(AC7,3),AC7),IF(H7>=4,MAX(AC7,H7),IF(C7="Memecoin",MAX(AC7,3),MAX(AC7,MIN(H7,AC7+1)))))) -> 2 | AE7: =IF(C7="","",IF(SUMPRODUCT((INDEX(Settings!$B$31:$P$34,MATCH(C7,Settings!$A$31:$A$34,0),0)=1)*(I7:W7<>"NA"))>0,"Group NA missing","OK")) -> OK
A8: XRP | B8: XRP Ledger | C8: Chain / protocol | D8: =IF(AA8=0,"",ROUND(AB8/AA8*100,1)) -> 73.8 | E8: =IF(D8="","",ROUND(D8/10,1)) -> 7.4 | F8: =IF(Z8=0,0,AA8/Z8) -> 1 | G8: =IF(D8="","",IF(F8<Settings!$B$42,"Not rated (low coverage)",CHOOSE(AD8,"Exceptional","Strong","Average/Decent","Weak"))) -> Average/Decent | I8: B | J8: C | K8: C | L8: C | M8: A | N8: D | O8: B | P8: C | Q8: A | R8: C | S8: A | T8: A | U8: A | V8: B | W8: B | X8: 2026-10-05 | Y8: ripple | Z8: =SUMPRODUCT(--(I8:W8<>"NA"),I$3:W$3) -> 100 | AA8: =SUMPRODUCT(--(I8:W8<>""),--(I8:W8<>"NA"),I$3:W$3) -> 100 | AB8: =SUMPRODUCT((I8:W8="A")*Settings!$B$4+(I8:W8="B")*Settings!$B$5+(I8:W8="C")*Settings!$B$6+(I8:W8="D")*Settings!$B$7+(I8:W8="E")*Settings!$B$8,I$3:W$3) -> 73.75 | AC8: =IF(D8="","",IF(D8>=Settings!$B$39,1,IF(D8>=Settings!$B$40,2,IF(D8>=Settings!$B$41,3,4)))) -> 3 | AD8: =IF(AC8="","",IF(H8="",IF(C8="Memecoin",MAX(AC8,3),AC8),IF(H8>=4,MAX(AC8,H8),IF(C8="Memecoin",MAX(AC8,3),MAX(AC8,MIN(H8,AC8+1)))))) -> 3 | AE8: =IF(C8="","",IF(SUMPRODUCT((INDEX(Settings!$B$31:$P$34,MATCH(C8,Settings!$A$31:$A$34,0),0)=1)*(I8:W8<>"NA"))>0,"Group NA missing","OK")) -> OK
A9: NEAR | B9: NEAR Protocol | C9: Chain / protocol | D9: =IF(AA9=0,"",ROUND(AB9/AA9*100,1)) -> 73.7 | E9: =IF(D9="","",ROUND(D9/10,1)) -> 7.4 | F9: =IF(Z9=0,0,AA9/Z9) -> 0.95 | G9: =IF(D9="","",IF(F9<Settings!$B$42,"Not rated (low coverage)",CHOOSE(AD9,"Exceptional","Strong","Average/Decent","Weak"))) -> Average/Decent | H9: 3 | I9: A | J9: A | K9: D | L9: C | M9: A | N9: D | O9: B | P9: C | Q9: B | R9: C | S9: A | T9: A | V9: C | W9: A | X9: 2026-10-05 | Y9: near | Z9: =SUMPRODUCT(--(I9:W9<>"NA"),I$3:W$3) -> 100 | AA9: =SUMPRODUCT(--(I9:W9<>""),--(I9:W9<>"NA"),I$3:W$3) -> 95 | AB9: =SUMPRODUCT((I9:W9="A")*Settings!$B$4+(I9:W9="B")*Settings!$B$5+(I9:W9="C")*Settings!$B$6+(I9:W9="D")*Settings!$B$7+(I9:W9="E")*Settings!$B$8,I$3:W$3) -> 70 | AC9: =IF(D9="","",IF(D9>=Settings!$B$39,1,IF(D9>=Settings!$B$40,2,IF(D9>=Settings!$B$41,3,4)))) -> 3 | AD9: =IF(AC9="","",IF(H9="",IF(C9="Memecoin",MAX(AC9,3),AC9),IF(H9>=4,MAX(AC9,H9),IF(C9="Memecoin",MAX(AC9,3),MAX(AC9,MIN(H9,AC9+1)))))) -> 3 | AE9: =IF(C9="","",IF(SUMPRODUCT((INDEX(Settings!$B$31:$P$34,MATCH(C9,Settings!$A$31:$A$34,0),0)=1)*(I9:W9<>"NA"))>0,"Group NA missing","OK")) -> OK
A10: LINK | B10: Chainlink | C10: Chain / protocol | D10: =IF(AA10=0,"",ROUND(AB10/AA10*100,1)) -> 75 | E10: =IF(D10="","",ROUND(D10/10,1)) -> 7.5 | F10: =IF(Z10=0,0,AA10/Z10) -> 1 | G10: =IF(D10="","",IF(F10<Settings!$B$42,"Not rated (low coverage)",CHOOSE(AD10,"Exceptional","Strong","Average/Decent","Weak"))) -> Strong | I10: B | J10: B | K10: E | L10: A | M10: A | N10: C | O10: C | P10: B | Q10: B | R10: C | S10: A | T10: B | U10: A | V10: B | W10: A | X10: 2026-10-05 | Y10: chainlink | Z10: =SUMPRODUCT(--(I10:W10<>"NA"),I$3:W$3) -> 100 | AA10: =SUMPRODUCT(--(I10:W10<>""),--(I10:W10<>"NA"),I$3:W$3) -> 100 | AB10: =SUMPRODUCT((I10:W10="A")*Settings!$B$4+(I10:W10="B")*Settings!$B$5+(I10:W10="C")*Settings!$B$6+(I10:W10="D")*Settings!$B$7+(I10:W10="E")*Settings!$B$8,I$3:W$3) -> 75 | AC10: =IF(D10="","",IF(D10>=Settings!$B$39,1,IF(D10>=Settings!$B$40,2,IF(D10>=Settings!$B$41,3,4)))) -> 2 | AD10: =IF(AC10="","",IF(H10="",IF(C10="Memecoin",MAX(AC10,3),AC10),IF(H10>=4,MAX(AC10,H10),IF(C10="Memecoin",MAX(AC10,3),MAX(AC10,MIN(H10,AC10+1)))))) -> 2 | AE10: =IF(C10="","",IF(SUMPRODUCT((INDEX(Settings!$B$31:$P$34,MATCH(C10,Settings!$A$31:$A$34,0),0)=1)*(I10:W10<>"NA"))>0,"Group NA missing","OK")) -> OK
A11: UNI | B11: Uniswap | C11: Chain / protocol | D11: =IF(AA11=0,"",ROUND(AB11/AA11*100,1)) -> 73.8 | E11: =IF(D11="","",ROUND(D11/10,1)) -> 7.4 | F11: =IF(Z11=0,0,AA11/Z11) -> 1 | G11: =IF(D11="","",IF(F11<Settings!$B$42,"Not rated (low coverage)",CHOOSE(AD11,"Exceptional","Strong","Average/Decent","Weak"))) -> Average/Decent | I11: B | J11: A | K11: C | L11: D | M11: A | N11: E | O11: B | P11: A | Q11: B | R11: B | S11: A | T11: A | U11: A | V11: C | W11: A | X11: 2026-10-05 | Y11: uniswap | Z11: =SUMPRODUCT(--(I11:W11<>"NA"),I$3:W$3) -> 100 | AA11: =SUMPRODUCT(--(I11:W11<>""),--(I11:W11<>"NA"),I$3:W$3) -> 100 | AB11: =SUMPRODUCT((I11:W11="A")*Settings!$B$4+(I11:W11="B")*Settings!$B$5+(I11:W11="C")*Settings!$B$6+(I11:W11="D")*Settings!$B$7+(I11:W11="E")*Settings!$B$8,I$3:W$3) -> 73.75 | AC11: =IF(D11="","",IF(D11>=Settings!$B$39,1,IF(D11>=Settings!$B$40,2,IF(D11>=Settings!$B$41,3,4)))) -> 3 | AD11: =IF(AC11="","",IF(H11="",IF(C11="Memecoin",MAX(AC11,3),AC11),IF(H11>=4,MAX(AC11,H11),IF(C11="Memecoin",MAX(AC11,3),MAX(AC11,MIN(H11,AC11+1)))))) -> 3 | AE11: =IF(C11="","",IF(SUMPRODUCT((INDEX(Settings!$B$31:$P$34,MATCH(C11,Settings!$A$31:$A$34,0),0)=1)*(I11:W11<>"NA"))>0,"Group NA missing","OK")) -> OK
A12: AAVE | B12: Aave | C12: Chain / protocol | D12: =IF(AA12=0,"",ROUND(AB12/AA12*100,1)) -> 78.9 | E12: =IF(D12="","",ROUND(D12/10,1)) -> 7.9 | F12: =IF(Z12=0,0,AA12/Z12) -> 0.95 | G12: =IF(D12="","",IF(F12<Settings!$B$42,"Not rated (low coverage)",CHOOSE(AD12,"Exceptional","Strong","Average/Decent","Weak"))) -> Strong | I12: A | J12: A | L12: E | M12: A | N12: D | O12: B | P12: B | Q12: A | R12: B | S12: A | T12: B | U12: A | V12: C | W12: A | X12: 2026-10-05 | Y12: aave | Z12: =SUMPRODUCT(--(I12:W12<>"NA"),I$3:W$3) -> 100 | AA12: =SUMPRODUCT(--(I12:W12<>""),--(I12:W12<>"NA"),I$3:W$3) -> 95 | AB12: =SUMPRODUCT((I12:W12="A")*Settings!$B$4+(I12:W12="B")*Settings!$B$5+(I12:W12="C")*Settings!$B$6+(I12:W12="D")*Settings!$B$7+(I12:W12="E")*Settings!$B$8,I$3:W$3) -> 75 | AC12: =IF(D12="","",IF(D12>=Settings!$B$39,1,IF(D12>=Settings!$B$40,2,IF(D12>=Settings!$B$41,3,4)))) -> 2 | AD12: =IF(AC12="","",IF(H12="",IF(C12="Memecoin",MAX(AC12,3),AC12),IF(H12>=4,MAX(AC12,H12),IF(C12="Memecoin",MAX(AC12,3),MAX(AC12,MIN(H12,AC12+1)))))) -> 2 | AE12: =IF(C12="","",IF(SUMPRODUCT((INDEX(Settings!$B$31:$P$34,MATCH(C12,Settings!$A$31:$A$34,0),0)=1)*(I12:W12<>"NA"))>0,"Group NA missing","OK")) -> OK
A13: ONDO | B13: Ondo | C13: Chain / protocol | D13: =IF(AA13=0,"",ROUND(AB13/AA13*100,1)) -> 68.8 | E13: =IF(D13="","",ROUND(D13/10,1)) -> 6.9 | F13: =IF(Z13=0,0,AA13/Z13) -> 1 | G13: =IF(D13="","",IF(F13<Settings!$B$42,"Not rated (low coverage)",CHOOSE(AD13,"Exceptional","Strong","Average/Decent","Weak"))) -> Average/Decent | I13: C | J13: A | K13: E | L13: E | M13: A | N13: C | O13: B | P13: A | Q13: B | R13: D | S13: A | T13: B | U13: A | V13: C | W13: A | X13: 2026-10-05 | Y13: ondo-finance | Z13: =SUMPRODUCT(--(I13:W13<>"NA"),I$3:W$3) -> 100 | AA13: =SUMPRODUCT(--(I13:W13<>""),--(I13:W13<>"NA"),I$3:W$3) -> 100 | AB13: =SUMPRODUCT((I13:W13="A")*Settings!$B$4+(I13:W13="B")*Settings!$B$5+(I13:W13="C")*Settings!$B$6+(I13:W13="D")*Settings!$B$7+(I13:W13="E")*Settings!$B$8,I$3:W$3) -> 68.75 | AC13: =IF(D13="","",IF(D13>=Settings!$B$39,1,IF(D13>=Settings!$B$40,2,IF(D13>=Settings!$B$41,3,4)))) -> 3 | AD13: =IF(AC13="","",IF(H13="",IF(C13="Memecoin",MAX(AC13,3),AC13),IF(H13>=4,MAX(AC13,H13),IF(C13="Memecoin",MAX(AC13,3),MAX(AC13,MIN(H13,AC13+1)))))) -> 3 | AE13: =IF(C13="","",IF(SUMPRODUCT((INDEX(Settings!$B$31:$P$34,MATCH(C13,Settings!$A$31:$A$34,0),0)=1)*(I13:W13<>"NA"))>0,"Group NA missing","OK")) -> OK
A14: TAO | B14: Bittensor | C14: Chain / protocol | D14: =IF(AA14=0,"",ROUND(AB14/AA14*100,1)) -> 68.1 | E14: =IF(D14="","",ROUND(D14/10,1)) -> 6.8 | F14: =IF(Z14=0,0,AA14/Z14) -> 0.94736842 | G14: =IF(D14="","",IF(F14<Settings!$B$42,"Not rated (low coverage)",CHOOSE(AD14,"Exceptional","Strong","Average/Decent","Weak"))) -> Average/Decent | I14: C | J14: B | K14: A | L14: E | M14: A | N14: C | O14: B | P14: B | Q14: C | R14: C | S14: A | T14: NA | V14: C | W14: A | X14: 2026-10-05 | Y14: bittensor | Z14: =SUMPRODUCT(--(I14:W14<>"NA"),I$3:W$3) -> 95 | AA14: =SUMPRODUCT(--(I14:W14<>""),--(I14:W14<>"NA"),I$3:W$3) -> 90 | AB14: =SUMPRODUCT((I14:W14="A")*Settings!$B$4+(I14:W14="B")*Settings!$B$5+(I14:W14="C")*Settings!$B$6+(I14:W14="D")*Settings!$B$7+(I14:W14="E")*Settings!$B$8,I$3:W$3) -> 61.25 | AC14: =IF(D14="","",IF(D14>=Settings!$B$39,1,IF(D14>=Settings!$B$40,2,IF(D14>=Settings!$B$41,3,4)))) -> 3 | AD14: =IF(AC14="","",IF(H14="",IF(C14="Memecoin",MAX(AC14,3),AC14),IF(H14>=4,MAX(AC14,H14),IF(C14="Memecoin",MAX(AC14,3),MAX(AC14,MIN(H14,AC14+1)))))) -> 3 | AE14: =IF(C14="","",IF(SUMPRODUCT((INDEX(Settings!$B$31:$P$34,MATCH(C14,Settings!$A$31:$A$34,0),0)=1)*(I14:W14<>"NA"))>0,"Group NA missing","OK")) -> OK
A15: BNB | B15: BNB | C15: Chain / protocol | D15: =IF(AA15=0,"",ROUND(AB15/AA15*100,1)) -> 71.1 | E15: =IF(D15="","",ROUND(D15/10,1)) -> 7.1 | F15: =IF(Z15=0,0,AA15/Z15) -> 0.95 | G15: =IF(D15="","",IF(F15<Settings!$B$42,"Not rated (low coverage)",CHOOSE(AD15,"Exceptional","Strong","Average/Decent","Weak"))) -> Average/Decent | H15: 3 | I15: A | J15: A | K15: D | L15: C | M15: A | N15: D | O15: C | P15: A | Q15: C | R15: D | S15: A | T15: B | V15: A | W15: B | X15: 2026-10-05 | Y15: binancecoin | Z15: =SUMPRODUCT(--(I15:W15<>"NA"),I$3:W$3) -> 100 | AA15: =SUMPRODUCT(--(I15:W15<>""),--(I15:W15<>"NA"),I$3:W$3) -> 95 | AB15: =SUMPRODUCT((I15:W15="A")*Settings!$B$4+(I15:W15="B")*Settings!$B$5+(I15:W15="C")*Settings!$B$6+(I15:W15="D")*Settings!$B$7+(I15:W15="E")*Settings!$B$8,I$3:W$3) -> 67.5 | AC15: =IF(D15="","",IF(D15>=Settings!$B$39,1,IF(D15>=Settings!$B$40,2,IF(D15>=Settings!$B$41,3,4)))) -> 3 | AD15: =IF(AC15="","",IF(H15="",IF(C15="Memecoin",MAX(AC15,3),AC15),IF(H15>=4,MAX(AC15,H15),IF(C15="Memecoin",MAX(AC15,3),MAX(AC15,MIN(H15,AC15+1)))))) -> 3 | AE15: =IF(C15="","",IF(SUMPRODUCT((INDEX(Settings!$B$31:$P$34,MATCH(C15,Settings!$A$31:$A$34,0),0)=1)*(I15:W15<>"NA"))>0,"Group NA missing","OK")) -> OK
A16: RENDER | B16: Render | C16: Chain / protocol | D16: =IF(AA16=0,"",ROUND(AB16/AA16*100,1)) -> 79.2 | E16: =IF(D16="","",ROUND(D16/10,1)) -> 7.9 | F16: =IF(Z16=0,0,AA16/Z16) -> 0.9 | G16: =IF(D16="","",IF(F16<Settings!$B$42,"Not rated (low coverage)",CHOOSE(AD16,"Exceptional","Strong","Average/Decent","Weak"))) -> Strong | I16: A | J16: A | L16: C | M16: A | N16: A | O16: B | P16: B | Q16: C | R16: C | S16: A | T16: B | V16: C | W16: C | X16: 2026-10-05 | Y16: render-token | Z16: =SUMPRODUCT(--(I16:W16<>"NA"),I$3:W$3) -> 100 | AA16: =SUMPRODUCT(--(I16:W16<>""),--(I16:W16<>"NA"),I$3:W$3) -> 90 | AB16: =SUMPRODUCT((I16:W16="A")*Settings!$B$4+(I16:W16="B")*Settings!$B$5+(I16:W16="C")*Settings!$B$6+(I16:W16="D")*Settings!$B$7+(I16:W16="E")*Settings!$B$8,I$3:W$3) -> 71.25 | AC16: =IF(D16="","",IF(D16>=Settings!$B$39,1,IF(D16>=Settings!$B$40,2,IF(D16>=Settings!$B$41,3,4)))) -> 2 | AD16: =IF(AC16="","",IF(H16="",IF(C16="Memecoin",MAX(AC16,3),AC16),IF(H16>=4,MAX(AC16,H16),IF(C16="Memecoin",MAX(AC16,3),MAX(AC16,MIN(H16,AC16+1)))))) -> 2 | AE16: =IF(C16="","",IF(SUMPRODUCT((INDEX(Settings!$B$31:$P$34,MATCH(C16,Settings!$A$31:$A$34,0),0)=1)*(I16:W16<>"NA"))>0,"Group NA missing","OK")) -> OK
A17: SAND | B17: The Sandbox | C17: Chain / protocol | D17: =IF(AA17=0,"",ROUND(AB17/AA17*100,1)) -> 69.1 | E17: =IF(D17="","",ROUND(D17/10,1)) -> 6.9 | F17: =IF(Z17=0,0,AA17/Z17) -> 0.85 | G17: =IF(D17="","",IF(F17<Settings!$B$42,"Not rated (low coverage)",CHOOSE(AD17,"Exceptional","Strong","Average/Decent","Weak"))) -> Average/Decent | I17: A | J17: A | K17: E | L17: C | M17: B | O17: C | P17: C | Q17: C | R17: C | S17: A | T17: A | V17: D | W17: A | X17: 2026-10-05 | Y17: the-sandbox | Z17: =SUMPRODUCT(--(I17:W17<>"NA"),I$3:W$3) -> 100 | AA17: =SUMPRODUCT(--(I17:W17<>""),--(I17:W17<>"NA"),I$3:W$3) -> 85 | AB17: =SUMPRODUCT((I17:W17="A")*Settings!$B$4+(I17:W17="B")*Settings!$B$5+(I17:W17="C")*Settings!$B$6+(I17:W17="D")*Settings!$B$7+(I17:W17="E")*Settings!$B$8,I$3:W$3) -> 58.75 | AC17: =IF(D17="","",IF(D17>=Settings!$B$39,1,IF(D17>=Settings!$B$40,2,IF(D17>=Settings!$B$41,3,4)))) -> 3 | AD17: =IF(AC17="","",IF(H17="",IF(C17="Memecoin",MAX(AC17,3),AC17),IF(H17>=4,MAX(AC17,H17),IF(C17="Memecoin",MAX(AC17,3),MAX(AC17,MIN(H17,AC17+1)))))) -> 3 | AE17: =IF(C17="","",IF(SUMPRODUCT((INDEX(Settings!$B$31:$P$34,MATCH(C17,Settings!$A$31:$A$34,0),0)=1)*(I17:W17<>"NA"))>0,"Group NA missing","OK")) -> OK
A18: XMR | B18: Monero | C18: Money coin | D18: =IF(AA18=0,"",ROUND(AB18/AA18*100,1)) -> 77.9 | E18: =IF(D18="","",ROUND(D18/10,1)) -> 7.8 | F18: =IF(Z18=0,0,AA18/Z18) -> 0.94444444 | G18: =IF(D18="","",IF(F18<Settings!$B$42,"Not rated (low coverage)",CHOOSE(AD18,"Exceptional","Strong","Average/Decent","Weak"))) -> Strong | I18: A | J18: A | K18: A | L18: NA | M18: A | N18: D | O18: D | P18: B | Q18: C | R18: A | S18: A | T18: NA | V18: B | W18: A | X18: 2026-10-05 | Y18: monero | Z18: =SUMPRODUCT(--(I18:W18<>"NA"),I$3:W$3) -> 90 | AA18: =SUMPRODUCT(--(I18:W18<>""),--(I18:W18<>"NA"),I$3:W$3) -> 85 | AB18: =SUMPRODUCT((I18:W18="A")*Settings!$B$4+(I18:W18="B")*Settings!$B$5+(I18:W18="C")*Settings!$B$6+(I18:W18="D")*Settings!$B$7+(I18:W18="E")*Settings!$B$8,I$3:W$3) -> 66.25 | AC18: =IF(D18="","",IF(D18>=Settings!$B$39,1,IF(D18>=Settings!$B$40,2,IF(D18>=Settings!$B$41,3,4)))) -> 2 | AD18: =IF(AC18="","",IF(H18="",IF(C18="Memecoin",MAX(AC18,3),AC18),IF(H18>=4,MAX(AC18,H18),IF(C18="Memecoin",MAX(AC18,3),MAX(AC18,MIN(H18,AC18+1)))))) -> 2 | AE18: =IF(C18="","",IF(SUMPRODUCT((INDEX(Settings!$B$31:$P$34,MATCH(C18,Settings!$A$31:$A$34,0),0)=1)*(I18:W18<>"NA"))>0,"Group NA missing","OK")) -> OK
A19: ZEC | B19: Zcash | C19: Money coin | D19: =IF(AA19=0,"",ROUND(AB19/AA19*100,1)) -> 89.7 | E19: =IF(D19="","",ROUND(D19/10,1)) -> 9 | F19: =IF(Z19=0,0,AA19/Z19) -> 0.94444444 | G19: =IF(D19="","",IF(F19<Settings!$B$42,"Not rated (low coverage)",CHOOSE(AD19,"Exceptional","Strong","Average/Decent","Weak"))) -> Average/Decent | H19: 3 | I19: A | J19: A | K19: B | L19: NA | M19: A | N19: A | O19: C | P19: B | Q19: B | R19: A | S19: A | T19: NA | V19: B | W19: A | X19: 2026-10-05 | Y19: zcash | Z19: =SUMPRODUCT(--(I19:W19<>"NA"),I$3:W$3) -> 90 | AA19: =SUMPRODUCT(--(I19:W19<>""),--(I19:W19<>"NA"),I$3:W$3) -> 85 | AB19: =SUMPRODUCT((I19:W19="A")*Settings!$B$4+(I19:W19="B")*Settings!$B$5+(I19:W19="C")*Settings!$B$6+(I19:W19="D")*Settings!$B$7+(I19:W19="E")*Settings!$B$8,I$3:W$3) -> 76.25 | AC19: =IF(D19="","",IF(D19>=Settings!$B$39,1,IF(D19>=Settings!$B$40,2,IF(D19>=Settings!$B$41,3,4)))) -> 2 | AD19: =IF(AC19="","",IF(H19="",IF(C19="Memecoin",MAX(AC19,3),AC19),IF(H19>=4,MAX(AC19,H19),IF(C19="Memecoin",MAX(AC19,3),MAX(AC19,MIN(H19,AC19+1)))))) -> 3 | AE19: =IF(C19="","",IF(SUMPRODUCT((INDEX(Settings!$B$31:$P$34,MATCH(C19,Settings!$A$31:$A$34,0),0)=1)*(I19:W19<>"NA"))>0,"Group NA missing","OK")) -> OK
A20: DOGE | B20: Dogecoin | C20: Memecoin | D20: =IF(AA20=0,"",ROUND(AB20/AA20*100,1)) -> 77.9 | E20: =IF(D20="","",ROUND(D20/10,1)) -> 7.8 | F20: =IF(Z20=0,0,AA20/Z20) -> 0.94444444 | G20: =IF(D20="","",IF(F20<Settings!$B$42,"Not rated (low coverage)",CHOOSE(AD20,"Exceptional","Strong","Average/Decent","Weak"))) -> Average/Decent | H20: 3 | I20: A | J20: A | K20: A | L20: NA | M20: A | N20: B | O20: B | P20: B | Q20: A | R20: A | S20: E | T20: NA | V20: B | W20: C | X20: 2026-10-05 | Y20: dogecoin | Z20: =SUMPRODUCT(--(I20:W20<>"NA"),I$3:W$3) -> 90 | AA20: =SUMPRODUCT(--(I20:W20<>""),--(I20:W20<>"NA"),I$3:W$3) -> 85 | AB20: =SUMPRODUCT((I20:W20="A")*Settings!$B$4+(I20:W20="B")*Settings!$B$5+(I20:W20="C")*Settings!$B$6+(I20:W20="D")*Settings!$B$7+(I20:W20="E")*Settings!$B$8,I$3:W$3) -> 66.25 | AC20: =IF(D20="","",IF(D20>=Settings!$B$39,1,IF(D20>=Settings!$B$40,2,IF(D20>=Settings!$B$41,3,4)))) -> 2 | AD20: =IF(AC20="","",IF(H20="",IF(C20="Memecoin",MAX(AC20,3),AC20),IF(H20>=4,MAX(AC20,H20),IF(C20="Memecoin",MAX(AC20,3),MAX(AC20,MIN(H20,AC20+1)))))) -> 3 | AE20: =IF(C20="","",IF(SUMPRODUCT((INDEX(Settings!$B$31:$P$34,MATCH(C20,Settings!$A$31:$A$34,0),0)=1)*(I20:W20<>"NA"))>0,"Group NA missing","OK")) -> OK
A21: SHIB | B21: Shiba Inu | C21: Memecoin | D21: =IF(AA21=0,"",ROUND(AB21/AA21*100,1)) -> 60.9 | E21: =IF(D21="","",ROUND(D21/10,1)) -> 6.1 | F21: =IF(Z21=0,0,AA21/Z21) -> 0.88888889 | G21: =IF(D21="","",IF(F21<Settings!$B$42,"Not rated (low coverage)",CHOOSE(AD21,"Exceptional","Strong","Average/Decent","Weak"))) -> Average/Decent | H21: 3 | I21: A | J21: A | L21: NA | M21: B | N21: B | O21: C | P21: C | Q21: C | R21: C | S21: E | T21: NA | V21: C | W21: B | X21: 2026-10-05 | Y21: shiba-inu | Z21: =SUMPRODUCT(--(I21:W21<>"NA"),I$3:W$3) -> 90 | AA21: =SUMPRODUCT(--(I21:W21<>""),--(I21:W21<>"NA"),I$3:W$3) -> 80 | AB21: =SUMPRODUCT((I21:W21="A")*Settings!$B$4+(I21:W21="B")*Settings!$B$5+(I21:W21="C")*Settings!$B$6+(I21:W21="D")*Settings!$B$7+(I21:W21="E")*Settings!$B$8,I$3:W$3) -> 48.75 | AC21: =IF(D21="","",IF(D21>=Settings!$B$39,1,IF(D21>=Settings!$B$40,2,IF(D21>=Settings!$B$41,3,4)))) -> 3 | AD21: =IF(AC21="","",IF(H21="",IF(C21="Memecoin",MAX(AC21,3),AC21),IF(H21>=4,MAX(AC21,H21),IF(C21="Memecoin",MAX(AC21,3),MAX(AC21,MIN(H21,AC21+1)))))) -> 3 | AE21: =IF(C21="","",IF(SUMPRODUCT((INDEX(Settings!$B$31:$P$34,MATCH(C21,Settings!$A$31:$A$34,0),0)=1)*(I21:W21<>"NA"))>0,"Group NA missing","OK")) -> OK
A22: USDC | B22: USD Coin | C22: Stablecoin / RWA | D22: =IF(AA22=0,"",ROUND(AB22/AA22*100,1)) -> 78.8 | E22: =IF(D22="","",ROUND(D22/10,1)) -> 7.9 | F22: =IF(Z22=0,0,AA22/Z22) -> 1 | G22: =IF(D22="","",IF(F22<Settings!$B$42,"Not rated (low coverage)",CHOOSE(AD22,"Exceptional","Strong","Average/Decent","Weak"))) -> Strong | I22: NA | J22: NA | K22: NA | L22: NA | M22: A | N22: B | O22: D | P22: A | Q22: C | R22: B | S22: A | T22: NA | U22: A | V22: B | W22: NA | X22: 2026-10-05 | Y22: usd-coin | Z22: =SUMPRODUCT(--(I22:W22<>"NA"),I$3:W$3) -> 65 | AA22: =SUMPRODUCT(--(I22:W22<>""),--(I22:W22<>"NA"),I$3:W$3) -> 65 | AB22: =SUMPRODUCT((I22:W22="A")*Settings!$B$4+(I22:W22="B")*Settings!$B$5+(I22:W22="C")*Settings!$B$6+(I22:W22="D")*Settings!$B$7+(I22:W22="E")*Settings!$B$8,I$3:W$3) -> 51.25 | AC22: =IF(D22="","",IF(D22>=Settings!$B$39,1,IF(D22>=Settings!$B$40,2,IF(D22>=Settings!$B$41,3,4)))) -> 2 | AD22: =IF(AC22="","",IF(H22="",IF(C22="Memecoin",MAX(AC22,3),AC22),IF(H22>=4,MAX(AC22,H22),IF(C22="Memecoin",MAX(AC22,3),MAX(AC22,MIN(H22,AC22+1)))))) -> 2 | AE22: =IF(C22="","",IF(SUMPRODUCT((INDEX(Settings!$B$31:$P$34,MATCH(C22,Settings!$A$31:$A$34,0),0)=1)*(I22:W22<>"NA"))>0,"Group NA missing","OK")) -> OK
A23: USDT | B23: Tether | C23: Stablecoin / RWA | D23: =IF(AA23=0,"",ROUND(AB23/AA23*100,1)) -> 70.8 | E23: =IF(D23="","",ROUND(D23/10,1)) -> 7.1 | F23: =IF(Z23=0,0,AA23/Z23) -> 0.92307692 | G23: =IF(D23="","",IF(F23<Settings!$B$42,"Not rated (low coverage)",CHOOSE(AD23,"Exceptional","Strong","Average/Decent","Weak"))) -> Average/Decent | I23: NA | J23: NA | K23: NA | L23: NA | M23: A | N23: C | O23: C | P23: A | Q23: C | R23: E | S23: A | T23: NA | V23: A | W23: NA | X23: 2026-10-05 | Y23: tether | Z23: =SUMPRODUCT(--(I23:W23<>"NA"),I$3:W$3) -> 65 | AA23: =SUMPRODUCT(--(I23:W23<>""),--(I23:W23<>"NA"),I$3:W$3) -> 60 | AB23: =SUMPRODUCT((I23:W23="A")*Settings!$B$4+(I23:W23="B")*Settings!$B$5+(I23:W23="C")*Settings!$B$6+(I23:W23="D")*Settings!$B$7+(I23:W23="E")*Settings!$B$8,I$3:W$3) -> 42.5 | AC23: =IF(D23="","",IF(D23>=Settings!$B$39,1,IF(D23>=Settings!$B$40,2,IF(D23>=Settings!$B$41,3,4)))) -> 3 | AD23: =IF(AC23="","",IF(H23="",IF(C23="Memecoin",MAX(AC23,3),AC23),IF(H23>=4,MAX(AC23,H23),IF(C23="Memecoin",MAX(AC23,3),MAX(AC23,MIN(H23,AC23+1)))))) -> 3 | AE23: =IF(C23="","",IF(SUMPRODUCT((INDEX(Settings!$B$31:$P$34,MATCH(C23,Settings!$A$31:$A$34,0),0)=1)*(I23:W23<>"NA"))>0,"Group NA missing","OK")) -> OK
A24: LTC | B24: Litecoin | C24: Money coin | D24: =IF(AA24=0,"",ROUND(AB24/AA24*100,1)) -> 86.8 | E24: =IF(D24="","",ROUND(D24/10,1)) -> 8.7 | F24: =IF(Z24=0,0,AA24/Z24) -> 0.94444444 | G24: =IF(D24="","",IF(F24<Settings!$B$42,"Not rated (low coverage)",CHOOSE(AD24,"Exceptional","Strong","Average/Decent","Weak"))) -> Strong | I24: A | J24: A | K24: A | L24: NA | M24: A | N24: C | O24: B | P24: C | Q24: A | R24: A | S24: A | T24: NA | V24: C | W24: A | X24: 2026-10-05 | Y24: litecoin | Z24: =SUMPRODUCT(--(I24:W24<>"NA"),I$3:W$3) -> 90 | AA24: =SUMPRODUCT(--(I24:W24<>""),--(I24:W24<>"NA"),I$3:W$3) -> 85 | AB24: =SUMPRODUCT((I24:W24="A")*Settings!$B$4+(I24:W24="B")*Settings!$B$5+(I24:W24="C")*Settings!$B$6+(I24:W24="D")*Settings!$B$7+(I24:W24="E")*Settings!$B$8,I$3:W$3) -> 73.75 | AC24: =IF(D24="","",IF(D24>=Settings!$B$39,1,IF(D24>=Settings!$B$40,2,IF(D24>=Settings!$B$41,3,4)))) -> 2 | AD24: =IF(AC24="","",IF(H24="",IF(C24="Memecoin",MAX(AC24,3),AC24),IF(H24>=4,MAX(AC24,H24),IF(C24="Memecoin",MAX(AC24,3),MAX(AC24,MIN(H24,AC24+1)))))) -> 2 | AE24: =IF(C24="","",IF(SUMPRODUCT((INDEX(Settings!$B$31:$P$34,MATCH(C24,Settings!$A$31:$A$34,0),0)=1)*(I24:W24<>"NA"))>0,"Group NA missing","OK")) -> OK
A25: HYPE | B25: Hyperliquid | C25: Chain / protocol | D25: =IF(AA25=0,"",ROUND(AB25/AA25*100,1)) -> 60.9 | E25: =IF(D25="","",ROUND(D25/10,1)) -> 6.1 | F25: =IF(Z25=0,0,AA25/Z25) -> 0.84210526 | G25: =IF(D25="","",IF(F25<Settings!$B$42,"Not rated (low coverage)",CHOOSE(AD25,"Exceptional","Strong","Average/Decent","Weak"))) -> Average/Decent | I25: D | J25: E | K25: C | L25: A | M25: A | N25: E | O25: B | P25: C | S25: A | T25: NA | U25: A | V25: B | W25: B | X25: 2026-10-05 | Y25: hyperliquid | Z25: =SUMPRODUCT(--(I25:W25<>"NA"),I$3:W$3) -> 95 | AA25: =SUMPRODUCT(--(I25:W25<>""),--(I25:W25<>"NA"),I$3:W$3) -> 80 | AB25: =SUMPRODUCT((I25:W25="A")*Settings!$B$4+(I25:W25="B")*Settings!$B$5+(I25:W25="C")*Settings!$B$6+(I25:W25="D")*Settings!$B$7+(I25:W25="E")*Settings!$B$8,I$3:W$3) -> 48.75 | AC25: =IF(D25="","",IF(D25>=Settings!$B$39,1,IF(D25>=Settings!$B$40,2,IF(D25>=Settings!$B$41,3,4)))) -> 3 | AD25: =IF(AC25="","",IF(H25="",IF(C25="Memecoin",MAX(AC25,3),AC25),IF(H25>=4,MAX(AC25,H25),IF(C25="Memecoin",MAX(AC25,3),MAX(AC25,MIN(H25,AC25+1)))))) -> 3 | AE25: =IF(C25="","",IF(SUMPRODUCT((INDEX(Settings!$B$31:$P$34,MATCH(C25,Settings!$A$31:$A$34,0),0)=1)*(I25:W25<>"NA"))>0,"Group NA missing","OK")) -> OK
A26: QNT | B26: Quant | C26: Chain / protocol | D26: =IF(AA26=0,"",ROUND(AB26/AA26*100,1)) -> 76.7 | E26: =IF(D26="","",ROUND(D26/10,1)) -> 7.7 | F26: =IF(Z26=0,0,AA26/Z26) -> 0.75 | G26: =IF(D26="","",IF(F26<Settings!$B$42,"Not rated (low coverage)",CHOOSE(AD26,"Exceptional","Strong","Average/Decent","Weak"))) -> Strong | I26: A | M26: A | O26: D | P26: B | Q26: C | R26: D | S26: A | T26: B | U26: A | V26: C | W26: A | X26: 2026-10-05 | Y26: quant-network | Z26: =SUMPRODUCT(--(I26:W26<>"NA"),I$3:W$3) -> 100 | AA26: =SUMPRODUCT(--(I26:W26<>""),--(I26:W26<>"NA"),I$3:W$3) -> 75 | AB26: =SUMPRODUCT((I26:W26="A")*Settings!$B$4+(I26:W26="B")*Settings!$B$5+(I26:W26="C")*Settings!$B$6+(I26:W26="D")*Settings!$B$7+(I26:W26="E")*Settings!$B$8,I$3:W$3) -> 57.5 | AC26: =IF(D26="","",IF(D26>=Settings!$B$39,1,IF(D26>=Settings!$B$40,2,IF(D26>=Settings!$B$41,3,4)))) -> 2 | AD26: =IF(AC26="","",IF(H26="",IF(C26="Memecoin",MAX(AC26,3),AC26),IF(H26>=4,MAX(AC26,H26),IF(C26="Memecoin",MAX(AC26,3),MAX(AC26,MIN(H26,AC26+1)))))) -> 2 | AE26: =IF(C26="","",IF(SUMPRODUCT((INDEX(Settings!$B$31:$P$34,MATCH(C26,Settings!$A$31:$A$34,0),0)=1)*(I26:W26<>"NA"))>0,"Group NA missing","OK")) -> OK
A27: IMX | B27: Immutable | C27: Chain / protocol | D27: =IF(AA27=0,"",ROUND(AB27/AA27*100,1)) -> 58.8 | E27: =IF(D27="","",ROUND(D27/10,1)) -> 5.9 | F27: =IF(Z27=0,0,AA27/Z27) -> 0.85 | G27: =IF(D27="","",IF(F27<Settings!$B$42,"Not rated (low coverage)",CHOOSE(AD27,"Exceptional","Strong","Average/Decent","Weak"))) -> Weak | I27: C | J27: A | K27: D | M27: D | N27: D | O27: D | P27: A | Q27: B | S27: A | T27: A | V27: D | W27: B | X27: 2026-10-05 | Y27: immutable-x | Z27: =SUMPRODUCT(--(I27:W27<>"NA"),I$3:W$3) -> 100 | AA27: =SUMPRODUCT(--(I27:W27<>""),--(I27:W27<>"NA"),I$3:W$3) -> 85 | AB27: =SUMPRODUCT((I27:W27="A")*Settings!$B$4+(I27:W27="B")*Settings!$B$5+(I27:W27="C")*Settings!$B$6+(I27:W27="D")*Settings!$B$7+(I27:W27="E")*Settings!$B$8,I$3:W$3) -> 50 | AC27: =IF(D27="","",IF(D27>=Settings!$B$39,1,IF(D27>=Settings!$B$40,2,IF(D27>=Settings!$B$41,3,4)))) -> 4 | AD27: =IF(AC27="","",IF(H27="",IF(C27="Memecoin",MAX(AC27,3),AC27),IF(H27>=4,MAX(AC27,H27),IF(C27="Memecoin",MAX(AC27,3),MAX(AC27,MIN(H27,AC27+1)))))) -> 4 | AE27: =IF(C27="","",IF(SUMPRODUCT((INDEX(Settings!$B$31:$P$34,MATCH(C27,Settings!$A$31:$A$34,0),0)=1)*(I27:W27<>"NA"))>0,"Group NA missing","OK")) -> OK
A28: PAXG | B28: PAX Gold | C28: Stablecoin / RWA | D28: =IF(AA28=0,"",ROUND(AB28/AA28*100,1)) -> 75 | E28: =IF(D28="","",ROUND(D28/10,1)) -> 7.5 | F28: =IF(Z28=0,0,AA28/Z28) -> 0.76923077 | G28: =IF(D28="","",IF(F28<Settings!$B$42,"Not rated (low coverage)",CHOOSE(AD28,"Exceptional","Strong","Average/Decent","Weak"))) -> Strong | I28: NA | J28: NA | K28: NA | L28: NA | M28: A | O28: C | P28: A | Q28: C | R28: C | S28: A | T28: NA | V28: C | W28: NA | X28: 2026-10-05 | Y28: pax-gold | Z28: =SUMPRODUCT(--(I28:W28<>"NA"),I$3:W$3) -> 65 | AA28: =SUMPRODUCT(--(I28:W28<>""),--(I28:W28<>"NA"),I$3:W$3) -> 50 | AB28: =SUMPRODUCT((I28:W28="A")*Settings!$B$4+(I28:W28="B")*Settings!$B$5+(I28:W28="C")*Settings!$B$6+(I28:W28="D")*Settings!$B$7+(I28:W28="E")*Settings!$B$8,I$3:W$3) -> 37.5 | AC28: =IF(D28="","",IF(D28>=Settings!$B$39,1,IF(D28>=Settings!$B$40,2,IF(D28>=Settings!$B$41,3,4)))) -> 2 | AD28: =IF(AC28="","",IF(H28="",IF(C28="Memecoin",MAX(AC28,3),AC28),IF(H28>=4,MAX(AC28,H28),IF(C28="Memecoin",MAX(AC28,3),MAX(AC28,MIN(H28,AC28+1)))))) -> 2 | AE28: =IF(C28="","",IF(SUMPRODUCT((INDEX(Settings!$B$31:$P$34,MATCH(C28,Settings!$A$31:$A$34,0),0)=1)*(I28:W28<>"NA"))>0,"Group NA missing","OK")) -> OK
A29: RED | B29: RedStone | C29: Chain / protocol | D29: =IF(AA29=0,"",ROUND(AB29/AA29*100,1)) -> 46.4 | E29: =IF(D29="","",ROUND(D29/10,1)) -> 4.6 | F29: =IF(Z29=0,0,AA29/Z29) -> 0.7 | G29: =IF(D29="","",IF(F29<Settings!$B$42,"Not rated (low coverage)",CHOOSE(AD29,"Exceptional","Strong","Average/Decent","Weak"))) -> Weak | I29: C | J29: E | K29: E | M29: D | O29: C | P29: A | Q29: C | T29: C | U29: A | V29: E | W29: A | X29: 2026-10-05 | Y29: redstone-oracles | Z29: =SUMPRODUCT(--(I29:W29<>"NA"),I$3:W$3) -> 100 | AA29: =SUMPRODUCT(--(I29:W29<>""),--(I29:W29<>"NA"),I$3:W$3) -> 70 | AB29: =SUMPRODUCT((I29:W29="A")*Settings!$B$4+(I29:W29="B")*Settings!$B$5+(I29:W29="C")*Settings!$B$6+(I29:W29="D")*Settings!$B$7+(I29:W29="E")*Settings!$B$8,I$3:W$3) -> 32.5 | AC29: =IF(D29="","",IF(D29>=Settings!$B$39,1,IF(D29>=Settings!$B$40,2,IF(D29>=Settings!$B$41,3,4)))) -> 4 | AD29: =IF(AC29="","",IF(H29="",IF(C29="Memecoin",MAX(AC29,3),AC29),IF(H29>=4,MAX(AC29,H29),IF(C29="Memecoin",MAX(AC29,3),MAX(AC29,MIN(H29,AC29+1)))))) -> 4 | AE29: =IF(C29="","",IF(SUMPRODUCT((INDEX(Settings!$B$31:$P$34,MATCH(C29,Settings!$A$31:$A$34,0),0)=1)*(I29:W29<>"NA"))>0,"Group NA missing","OK")) -> OK
A30: FET | B30: Artificial Superintelligence Alliance | C30: Chain / protocol | D30: =IF(AA30=0,"",ROUND(AB30/AA30*100,1)) -> 71.4 | E30: =IF(D30="","",ROUND(D30/10,1)) -> 7.1 | F30: =IF(Z30=0,0,AA30/Z30) -> 0.7 | G30: =IF(D30="","",IF(F30<Settings!$B$42,"Not rated (low coverage)",CHOOSE(AD30,"Exceptional","Strong","Average/Decent","Weak"))) -> Average/Decent | H30: 3 | I30: A | J30: A | K30: C | M30: A | O30: B | P30: C | Q30: C | R30: D | T30: B | V30: D | W30: A | X30: 2026-10-05 | Y30: fetch-ai | Z30: =SUMPRODUCT(--(I30:W30<>"NA"),I$3:W$3) -> 100 | AA30: =SUMPRODUCT(--(I30:W30<>""),--(I30:W30<>"NA"),I$3:W$3) -> 70 | AB30: =SUMPRODUCT((I30:W30="A")*Settings!$B$4+(I30:W30="B")*Settings!$B$5+(I30:W30="C")*Settings!$B$6+(I30:W30="D")*Settings!$B$7+(I30:W30="E")*Settings!$B$8,I$3:W$3) -> 50 | AC30: =IF(D30="","",IF(D30>=Settings!$B$39,1,IF(D30>=Settings!$B$40,2,IF(D30>=Settings!$B$41,3,4)))) -> 3 | AD30: =IF(AC30="","",IF(H30="",IF(C30="Memecoin",MAX(AC30,3),AC30),IF(H30>=4,MAX(AC30,H30),IF(C30="Memecoin",MAX(AC30,3),MAX(AC30,MIN(H30,AC30+1)))))) -> 3 | AE30: =IF(C30="","",IF(SUMPRODUCT((INDEX(Settings!$B$31:$P$34,MATCH(C30,Settings!$A$31:$A$34,0),0)=1)*(I30:W30<>"NA"))>0,"Group NA missing","OK")) -> OK
A31: RAY | B31: Raydium | C31: Chain / protocol | D31: =IF(AA31=0,"",ROUND(AB31/AA31*100,1)) -> 55.9 | E31: =IF(D31="","",ROUND(D31/10,1)) -> 5.6 | F31: =IF(Z31=0,0,AA31/Z31) -> 0.89473684 | G31: =IF(D31="","",IF(F31<Settings!$B$42,"Not rated (low coverage)",CHOOSE(AD31,"Exceptional","Strong","Average/Decent","Weak"))) -> Weak | I31: C | J31: A | L31: C | M31: C | N31: E | O31: B | P31: C | Q31: C | R31: C | S31: A | T31: NA | V31: D | W31: A | X31: 2026-10-05 | Y31: raydium | Z31: =SUMPRODUCT(--(I31:W31<>"NA"),I$3:W$3) -> 95 | AA31: =SUMPRODUCT(--(I31:W31<>""),--(I31:W31<>"NA"),I$3:W$3) -> 85 | AB31: =SUMPRODUCT((I31:W31="A")*Settings!$B$4+(I31:W31="B")*Settings!$B$5+(I31:W31="C")*Settings!$B$6+(I31:W31="D")*Settings!$B$7+(I31:W31="E")*Settings!$B$8,I$3:W$3) -> 47.5 | AC31: =IF(D31="","",IF(D31>=Settings!$B$39,1,IF(D31>=Settings!$B$40,2,IF(D31>=Settings!$B$41,3,4)))) -> 4 | AD31: =IF(AC31="","",IF(H31="",IF(C31="Memecoin",MAX(AC31,3),AC31),IF(H31>=4,MAX(AC31,H31),IF(C31="Memecoin",MAX(AC31,3),MAX(AC31,MIN(H31,AC31+1)))))) -> 4 | AE31: =IF(C31="","",IF(SUMPRODUCT((INDEX(Settings!$B$31:$P$34,MATCH(C31,Settings!$A$31:$A$34,0),0)=1)*(I31:W31<>"NA"))>0,"Group NA missing","OK")) -> OK
A32: NIGHT | B32: Midnight | C32: Chain / protocol | D32: =IF(AA32=0,"",ROUND(AB32/AA32*100,1)) -> 70 | E32: =IF(D32="","",ROUND(D32/10,1)) -> 7 | F32: =IF(Z32=0,0,AA32/Z32) -> 0.78947368 | G32: =IF(D32="","",IF(F32<Settings!$B$42,"Not rated (low coverage)",CHOOSE(AD32,"Exceptional","Strong","Average/Decent","Weak"))) -> Average/Decent | H32: 3 | I32: B | J32: A | K32: C | L32: E | M32: A | O32: B | P32: C | Q32: C | S32: A | T32: NA | V32: D | W32: A | X32: 2026-10-05 | Y32: midnight-3 | Z32: =SUMPRODUCT(--(I32:W32<>"NA"),I$3:W$3) -> 95 | AA32: =SUMPRODUCT(--(I32:W32<>""),--(I32:W32<>"NA"),I$3:W$3) -> 75 | AB32: =SUMPRODUCT((I32:W32="A")*Settings!$B$4+(I32:W32="B")*Settings!$B$5+(I32:W32="C")*Settings!$B$6+(I32:W32="D")*Settings!$B$7+(I32:W32="E")*Settings!$B$8,I$3:W$3) -> 52.5 | AC32: =IF(D32="","",IF(D32>=Settings!$B$39,1,IF(D32>=Settings!$B$40,2,IF(D32>=Settings!$B$41,3,4)))) -> 3 | AD32: =IF(AC32="","",IF(H32="",IF(C32="Memecoin",MAX(AC32,3),AC32),IF(H32>=4,MAX(AC32,H32),IF(C32="Memecoin",MAX(AC32,3),MAX(AC32,MIN(H32,AC32+1)))))) -> 3 | AE32: =IF(C32="","",IF(SUMPRODUCT((INDEX(Settings!$B$31:$P$34,MATCH(C32,Settings!$A$31:$A$34,0),0)=1)*(I32:W32<>"NA"))>0,"Group NA missing","OK")) -> OK
A33: POWR | B33: Powerledger | C33: Chain / protocol | D33: =IF(AA33=0,"",ROUND(AB33/AA33*100,1)) -> 51.7 | E33: =IF(D33="","",ROUND(D33/10,1)) -> 5.2 | F33: =IF(Z33=0,0,AA33/Z33) -> 0.75 | G33: =IF(D33="","",IF(F33<Settings!$B$42,"Not rated (low coverage)",CHOOSE(AD33,"Exceptional","Strong","Average/Decent","Weak"))) -> Weak | I33: C | J33: D | M33: E | O33: D | P33: A | Q33: D | S33: A | T33: B | U33: A | V33: E | W33: A | X33: 2026-10-05 | Y33: power-ledger | Z33: =SUMPRODUCT(--(I33:W33<>"NA"),I$3:W$3) -> 100 | AA33: =SUMPRODUCT(--(I33:W33<>""),--(I33:W33<>"NA"),I$3:W$3) -> 75 | AB33: =SUMPRODUCT((I33:W33="A")*Settings!$B$4+(I33:W33="B")*Settings!$B$5+(I33:W33="C")*Settings!$B$6+(I33:W33="D")*Settings!$B$7+(I33:W33="E")*Settings!$B$8,I$3:W$3) -> 38.75 | AC33: =IF(D33="","",IF(D33>=Settings!$B$39,1,IF(D33>=Settings!$B$40,2,IF(D33>=Settings!$B$41,3,4)))) -> 4 | AD33: =IF(AC33="","",IF(H33="",IF(C33="Memecoin",MAX(AC33,3),AC33),IF(H33>=4,MAX(AC33,H33),IF(C33="Memecoin",MAX(AC33,3),MAX(AC33,MIN(H33,AC33+1)))))) -> 4 | AE33: =IF(C33="","",IF(SUMPRODUCT((INDEX(Settings!$B$31:$P$34,MATCH(C33,Settings!$A$31:$A$34,0),0)=1)*(I33:W33<>"NA"))>0,"Group NA missing","OK")) -> OK
A34: PEPE | B34: Pepe | C34: Memecoin | D34: =IF(AA34=0,"",ROUND(AB34/AA34*100,1)) -> 71.4 | E34: =IF(D34="","",ROUND(D34/10,1)) -> 7.1 | F34: =IF(Z34=0,0,AA34/Z34) -> 0.77777778 | G34: =IF(D34="","",IF(F34<Settings!$B$42,"Not rated (low coverage)",CHOOSE(AD34,"Exceptional","Strong","Average/Decent","Weak"))) -> Average/Decent | H34: 3 | I34: A | J34: A | K34: A | L34: NA | M34: A | O34: C | P34: A | R34: A | S34: E | T34: NA | U34: E | V34: C | W34: A | X34: 2026-10-05 | Y34: pepe | Z34: =SUMPRODUCT(--(I34:W34<>"NA"),I$3:W$3) -> 90 | AA34: =SUMPRODUCT(--(I34:W34<>""),--(I34:W34<>"NA"),I$3:W$3) -> 70 | AB34: =SUMPRODUCT((I34:W34="A")*Settings!$B$4+(I34:W34="B")*Settings!$B$5+(I34:W34="C")*Settings!$B$6+(I34:W34="D")*Settings!$B$7+(I34:W34="E")*Settings!$B$8,I$3:W$3) -> 50 | AC34: =IF(D34="","",IF(D34>=Settings!$B$39,1,IF(D34>=Settings!$B$40,2,IF(D34>=Settings!$B$41,3,4)))) -> 3 | AD34: =IF(AC34="","",IF(H34="",IF(C34="Memecoin",MAX(AC34,3),AC34),IF(H34>=4,MAX(AC34,H34),IF(C34="Memecoin",MAX(AC34,3),MAX(AC34,MIN(H34,AC34+1)))))) -> 3 | AE34: =IF(C34="","",IF(SUMPRODUCT((INDEX(Settings!$B$31:$P$34,MATCH(C34,Settings!$A$31:$A$34,0),0)=1)*(I34:W34<>"NA"))>0,"Group NA missing","OK")) -> OK
A35: CRO | B35: Cronos | C35: Chain / protocol | D35: =IF(AA35=0,"",ROUND(AB35/AA35*100,1)) -> 47.4 | E35: =IF(D35="","",ROUND(D35/10,1)) -> 4.7 | F35: =IF(Z35=0,0,AA35/Z35) -> 0.95 | G35: =IF(D35="","",IF(F35<Settings!$B$42,"Not rated (low coverage)",CHOOSE(AD35,"Exceptional","Strong","Average/Decent","Weak"))) -> Weak | H35: 3 | I35: C | J35: D | K35: E | M35: D | N35: E | O35: D | P35: D | Q35: B | R35: D | S35: A | T35: A | U35: A | V35: C | W35: C | X35: 2026-10-05 | Y35: crypto-com-chain | Z35: =SUMPRODUCT(--(I35:W35<>"NA"),I$3:W$3) -> 100 | AA35: =SUMPRODUCT(--(I35:W35<>""),--(I35:W35<>"NA"),I$3:W$3) -> 95 | AB35: =SUMPRODUCT((I35:W35="A")*Settings!$B$4+(I35:W35="B")*Settings!$B$5+(I35:W35="C")*Settings!$B$6+(I35:W35="D")*Settings!$B$7+(I35:W35="E")*Settings!$B$8,I$3:W$3) -> 45 | AC35: =IF(D35="","",IF(D35>=Settings!$B$39,1,IF(D35>=Settings!$B$40,2,IF(D35>=Settings!$B$41,3,4)))) -> 4 | AD35: =IF(AC35="","",IF(H35="",IF(C35="Memecoin",MAX(AC35,3),AC35),IF(H35>=4,MAX(AC35,H35),IF(C35="Memecoin",MAX(AC35,3),MAX(AC35,MIN(H35,AC35+1)))))) -> 4 | AE35: =IF(C35="","",IF(SUMPRODUCT((INDEX(Settings!$B$31:$P$34,MATCH(C35,Settings!$A$31:$A$34,0),0)=1)*(I35:W35<>"NA"))>0,"Group NA missing","OK")) -> OK
A36: AVAX | B36: Avalanche | C36: Chain / protocol | D36: =IF(AA36=0,"",ROUND(AB36/AA36*100,1)) -> 78.9 | E36: =IF(D36="","",ROUND(D36/10,1)) -> 7.9 | F36: =IF(Z36=0,0,AA36/Z36) -> 0.95 | G36: =IF(D36="","",IF(F36<Settings!$B$42,"Not rated (low coverage)",CHOOSE(AD36,"Exceptional","Strong","Average/Decent","Weak"))) -> Strong | I36: B | J36: B | K36: C | L36: B | M36: A | N36: D | O36: C | P36: A | Q36: A | S36: A | T36: A | U36: A | V36: C | W36: A | X36: 2026-10-05 | Y36: avalanche-2 | Z36: =SUMPRODUCT(--(I36:W36<>"NA"),I$3:W$3) -> 100 | AA36: =SUMPRODUCT(--(I36:W36<>""),--(I36:W36<>"NA"),I$3:W$3) -> 95 | AB36: =SUMPRODUCT((I36:W36="A")*Settings!$B$4+(I36:W36="B")*Settings!$B$5+(I36:W36="C")*Settings!$B$6+(I36:W36="D")*Settings!$B$7+(I36:W36="E")*Settings!$B$8,I$3:W$3) -> 75 | AC36: =IF(D36="","",IF(D36>=Settings!$B$39,1,IF(D36>=Settings!$B$40,2,IF(D36>=Settings!$B$41,3,4)))) -> 2 | AD36: =IF(AC36="","",IF(H36="",IF(C36="Memecoin",MAX(AC36,3),AC36),IF(H36>=4,MAX(AC36,H36),IF(C36="Memecoin",MAX(AC36,3),MAX(AC36,MIN(H36,AC36+1)))))) -> 2 | AE36: =IF(C36="","",IF(SUMPRODUCT((INDEX(Settings!$B$31:$P$34,MATCH(C36,Settings!$A$31:$A$34,0),0)=1)*(I36:W36<>"NA"))>0,"Group NA missing","OK")) -> OK
A37: HBAR | B37: Hedera | C37: Chain / protocol | D37: =IF(AA37=0,"",ROUND(AB37/AA37*100,1)) -> 72.2 | E37: =IF(D37="","",ROUND(D37/10,1)) -> 7.2 | F37: =IF(Z37=0,0,AA37/Z37) -> 0.9 | G37: =IF(D37="","",IF(F37<Settings!$B$42,"Not rated (low coverage)",CHOOSE(AD37,"Exceptional","Strong","Average/Decent","Weak"))) -> Average/Decent | I37: A | J37: A | K37: D | L37: E | M37: A | N37: E | O37: C | P37: A | Q37: A | S37: A | T37: A | V37: C | W37: B | X37: 2026-10-05 | Y37: hedera-hashgraph | Z37: =SUMPRODUCT(--(I37:W37<>"NA"),I$3:W$3) -> 100 | AA37: =SUMPRODUCT(--(I37:W37<>""),--(I37:W37<>"NA"),I$3:W$3) -> 90 | AB37: =SUMPRODUCT((I37:W37="A")*Settings!$B$4+(I37:W37="B")*Settings!$B$5+(I37:W37="C")*Settings!$B$6+(I37:W37="D")*Settings!$B$7+(I37:W37="E")*Settings!$B$8,I$3:W$3) -> 65 | AC37: =IF(D37="","",IF(D37>=Settings!$B$39,1,IF(D37>=Settings!$B$40,2,IF(D37>=Settings!$B$41,3,4)))) -> 3 | AD37: =IF(AC37="","",IF(H37="",IF(C37="Memecoin",MAX(AC37,3),AC37),IF(H37>=4,MAX(AC37,H37),IF(C37="Memecoin",MAX(AC37,3),MAX(AC37,MIN(H37,AC37+1)))))) -> 3 | AE37: =IF(C37="","",IF(SUMPRODUCT((INDEX(Settings!$B$31:$P$34,MATCH(C37,Settings!$A$31:$A$34,0),0)=1)*(I37:W37<>"NA"))>0,"Group NA missing","OK")) -> OK
A38: CAKE | B38: PancakeSwap | C38: Chain / protocol | D38: =IF(AA38=0,"",ROUND(AB38/AA38*100,1)) -> 54.4 | E38: =IF(D38="","",ROUND(D38/10,1)) -> 5.4 | F38: =IF(Z38=0,0,AA38/Z38) -> 0.85 | G38: =IF(D38="","",IF(F38<Settings!$B$42,"Not rated (low coverage)",CHOOSE(AD38,"Exceptional","Strong","Average/Decent","Weak"))) -> Weak | I38: B | J38: A | L38: C | M38: D | N38: E | O38: D | P38: A | Q38: C | S38: A | T38: D | V38: D | W38: A | X38: 2026-10-05 | Y38: pancakeswap-token | Z38: =SUMPRODUCT(--(I38:W38<>"NA"),I$3:W$3) -> 100 | AA38: =SUMPRODUCT(--(I38:W38<>""),--(I38:W38<>"NA"),I$3:W$3) -> 85 | AB38: =SUMPRODUCT((I38:W38="A")*Settings!$B$4+(I38:W38="B")*Settings!$B$5+(I38:W38="C")*Settings!$B$6+(I38:W38="D")*Settings!$B$7+(I38:W38="E")*Settings!$B$8,I$3:W$3) -> 46.25 | AC38: =IF(D38="","",IF(D38>=Settings!$B$39,1,IF(D38>=Settings!$B$40,2,IF(D38>=Settings!$B$41,3,4)))) -> 4 | AD38: =IF(AC38="","",IF(H38="",IF(C38="Memecoin",MAX(AC38,3),AC38),IF(H38>=4,MAX(AC38,H38),IF(C38="Memecoin",MAX(AC38,3),MAX(AC38,MIN(H38,AC38+1)))))) -> 4 | AE38: =IF(C38="","",IF(SUMPRODUCT((INDEX(Settings!$B$31:$P$34,MATCH(C38,Settings!$A$31:$A$34,0),0)=1)*(I38:W38<>"NA"))>0,"Group NA missing","OK")) -> OK
A39: SKY | B39: Sky | C39: Chain / protocol | D39: =IF(AA39=0,"",ROUND(AB39/AA39*100,1)) -> 64.1 | E39: =IF(D39="","",ROUND(D39/10,1)) -> 6.4 | F39: =IF(Z39=0,0,AA39/Z39) -> 0.8 | G39: =IF(D39="","",IF(F39<Settings!$B$42,"Not rated (low coverage)",CHOOSE(AD39,"Exceptional","Strong","Average/Decent","Weak"))) -> Average/Decent | I39: A | J39: A | L39: C | M39: D | N39: E | P39: A | Q39: C | S39: A | T39: B | V39: C | W39: A | X39: 2026-10-05 | Y39: sky | Z39: =SUMPRODUCT(--(I39:W39<>"NA"),I$3:W$3) -> 100 | AA39: =SUMPRODUCT(--(I39:W39<>""),--(I39:W39<>"NA"),I$3:W$3) -> 80 | AB39: =SUMPRODUCT((I39:W39="A")*Settings!$B$4+(I39:W39="B")*Settings!$B$5+(I39:W39="C")*Settings!$B$6+(I39:W39="D")*Settings!$B$7+(I39:W39="E")*Settings!$B$8,I$3:W$3) -> 51.25 | AC39: =IF(D39="","",IF(D39>=Settings!$B$39,1,IF(D39>=Settings!$B$40,2,IF(D39>=Settings!$B$41,3,4)))) -> 3 | AD39: =IF(AC39="","",IF(H39="",IF(C39="Memecoin",MAX(AC39,3),AC39),IF(H39>=4,MAX(AC39,H39),IF(C39="Memecoin",MAX(AC39,3),MAX(AC39,MIN(H39,AC39+1)))))) -> 3 | AE39: =IF(C39="","",IF(SUMPRODUCT((INDEX(Settings!$B$31:$P$34,MATCH(C39,Settings!$A$31:$A$34,0),0)=1)*(I39:W39<>"NA"))>0,"Group NA missing","OK")) -> OK
A40: XLM | B40: Stellar | C40: Chain / protocol | D40: =IF(AA40=0,"",ROUND(AB40/AA40*100,1)) -> 76.3 | E40: =IF(D40="","",ROUND(D40/10,1)) -> 7.6 | F40: =IF(Z40=0,0,AA40/Z40) -> 1 | G40: =IF(D40="","",IF(F40<Settings!$B$42,"Not rated (low coverage)",CHOOSE(AD40,"Exceptional","Strong","Average/Decent","Weak"))) -> Strong | I40: B | J40: B | K40: C | L40: D | M40: A | N40: B | O40: B | P40: A | Q40: A | R40: B | S40: A | T40: C | U40: A | V40: C | W40: D | X40: 2026-10-06 | Y40: stellar | Z40: =SUMPRODUCT(--(I40:W40<>"NA"),I$3:W$3) -> 100 | AA40: =SUMPRODUCT(--(I40:W40<>""),--(I40:W40<>"NA"),I$3:W$3) -> 100 | AB40: =SUMPRODUCT((I40:W40="A")*Settings!$B$4+(I40:W40="B")*Settings!$B$5+(I40:W40="C")*Settings!$B$6+(I40:W40="D")*Settings!$B$7+(I40:W40="E")*Settings!$B$8,I$3:W$3) -> 76.25 | AC40: =IF(D40="","",IF(D40>=Settings!$B$39,1,IF(D40>=Settings!$B$40,2,IF(D40>=Settings!$B$41,3,4)))) -> 2 | AD40: =IF(AC40="","",IF(H40="",IF(C40="Memecoin",MAX(AC40,3),AC40),IF(H40>=4,MAX(AC40,H40),IF(C40="Memecoin",MAX(AC40,3),MAX(AC40,MIN(H40,AC40+1)))))) -> 2 | AE40: =IF(C40="","",IF(SUMPRODUCT((INDEX(Settings!$B$31:$P$34,MATCH(C40,Settings!$A$31:$A$34,0),0)=1)*(I40:W40<>"NA"))>0,"Group NA missing","OK")) -> OK
...

Sheet Schedule
A1: SCHEDULE: when each coin is due for reassessment
A2: Held coins every 13 weeks, every other coin every 26 weeks; slots are spread so about the same number comes due each week. Written by crypto_review_schedule.py: run it after any coin is added or reassessed, or after buying or selling a coin, then re-import the calendar file.
A3: Schedule written 2026-10-08 (week of 2026-10-05).
J5: CALENDAR: the next 52 weeks
A6: Ticker | B6: Held | C6: Every (weeks) | D6: Last evaluated | E6: Next review (week of) | F6: Status | G6: Tier | H6: Last evaluated when scheduled | J6: Week of (Monday) | K6: Coins I hold (quarterly) | L6: Other coins (twice a year) | M6: Count
A7: BTC | B7: yes | C7: =IF(B7="yes",13,26) -> 13 | D7: =IFERROR(INDEX(Grades!$X:$X,MATCH(A7,Grades!$A:$A,0)),"") -> 2026-10-05 | E7: 46307 | F7: =IF(E7="","",IF(E7<TODAY()-WEEKDAY(TODAY(),3),"Overdue",IF(E7=TODAY()-WEEKDAY(TODAY(),3),"This week",IF(E7=TODAY()-WEEKDAY(TODAY(),3)+7,"Next week","")))) -> Next week | G7: =IFERROR(INDEX(Grades!$G:$G,MATCH(A7,Grades!$A:$A,0)),"") -> Exceptional | H7: 46300 | J7: 46300 | M7: 0
A8: ETH | B8: yes | C8: =IF(B8="yes",13,26) -> 13 | D8: =IFERROR(INDEX(Grades!$X:$X,MATCH(A8,Grades!$A:$A,0)),"") -> 2026-10-07 | E8: 46314 | F8: =IF(E8="","",IF(E8<TODAY()-WEEKDAY(TODAY(),3),"Overdue",IF(E8=TODAY()-WEEKDAY(TODAY(),3),"This week",IF(E8=TODAY()-WEEKDAY(TODAY(),3)+7,"Next week","")))) | G8: =IFERROR(INDEX(Grades!$G:$G,MATCH(A8,Grades!$A:$A,0)),"") -> Strong | H8: 46302 | J8: 46307 | K8: BTC, ENA | M8: 2
A9: SOL | B9: yes | C9: =IF(B9="yes",13,26) -> 13 | D9: =IFERROR(INDEX(Grades!$X:$X,MATCH(A9,Grades!$A:$A,0)),"") -> 2026-10-05 | E9: 46321 | F9: =IF(E9="","",IF(E9<TODAY()-WEEKDAY(TODAY(),3),"Overdue",IF(E9=TODAY()-WEEKDAY(TODAY(),3),"This week",IF(E9=TODAY()-WEEKDAY(TODAY(),3)+7,"Next week","")))) | G9: =IFERROR(INDEX(Grades!$G:$G,MATCH(A9,Grades!$A:$A,0)),"") -> Strong | H9: 46300 | J9: 46314 | K9: ETH | L9: XRP | M9: 2
A10: XRP | B10: no | C10: =IF(B10="yes",13,26) -> 26 | D10: =IFERROR(INDEX(Grades!$X:$X,MATCH(A10,Grades!$A:$A,0)),"") -> 2026-10-05 | E10: 46314 | F10: =IF(E10="","",IF(E10<TODAY()-WEEKDAY(TODAY(),3),"Overdue",IF(E10=TODAY()-WEEKDAY(TODAY(),3),"This week",IF(E10=TODAY()-WEEKDAY(TODAY(),3)+7,"Next week","")))) | G10: =IFERROR(INDEX(Grades!$G:$G,MATCH(A10,Grades!$A:$A,0)),"") -> Average/Decent | H10: 46300 | J10: 46321 | K10: SOL | L10: UNI | M10: 2
A11: NEAR | B11: yes | C11: =IF(B11="yes",13,26) -> 13 | D11: =IFERROR(INDEX(Grades!$X:$X,MATCH(A11,Grades!$A:$A,0)),"") -> 2026-10-05 | E11: 46328 | F11: =IF(E11="","",IF(E11<TODAY()-WEEKDAY(TODAY(),3),"Overdue",IF(E11=TODAY()-WEEKDAY(TODAY(),3),"This week",IF(E11=TODAY()-WEEKDAY(TODAY(),3)+7,"Next week","")))) | G11: =IFERROR(INDEX(Grades!$G:$G,MATCH(A11,Grades!$A:$A,0)),"") -> Average/Decent | H11: 46300 | J11: 46328 | K11: NEAR | L11: AAVE | M11: 2
A12: LINK | B12: yes | C12: =IF(B12="yes",13,26) -> 13 | D12: =IFERROR(INDEX(Grades!$X:$X,MATCH(A12,Grades!$A:$A,0)),"") -> 2026-10-05 | E12: 46335 | F12: =IF(E12="","",IF(E12<TODAY()-WEEKDAY(TODAY(),3),"Overdue",IF(E12=TODAY()-WEEKDAY(TODAY(),3),"This week",IF(E12=TODAY()-WEEKDAY(TODAY(),3)+7,"Next week","")))) | G12: =IFERROR(INDEX(Grades!$G:$G,MATCH(A12,Grades!$A:$A,0)),"") -> Strong | H12: 46300 | J12: 46335 | K12: LINK | L12: TAO | M12: 2
A13: UNI | B13: no | C13: =IF(B13="yes",13,26) -> 26 | D13: =IFERROR(INDEX(Grades!$X:$X,MATCH(A13,Grades!$A:$A,0)),"") -> 2026-10-05 | E13: 46321 | F13: =IF(E13="","",IF(E13<TODAY()-WEEKDAY(TODAY(),3),"Overdue",IF(E13=TODAY()-WEEKDAY(TODAY(),3),"This week",IF(E13=TODAY()-WEEKDAY(TODAY(),3)+7,"Next week","")))) | G13: =IFERROR(INDEX(Grades!$G:$G,MATCH(A13,Grades!$A:$A,0)),"") -> Average/Decent | H13: 46300 | J13: 46342 | K13: ONDO | L13: BNB | M13: 2
A14: AAVE | B14: no | C14: =IF(B14="yes",13,26) -> 26 | D14: =IFERROR(INDEX(Grades!$X:$X,MATCH(A14,Grades!$A:$A,0)),"") -> 2026-10-05 | E14: 46328 | F14: =IF(E14="","",IF(E14<TODAY()-WEEKDAY(TODAY(),3),"Overdue",IF(E14=TODAY()-WEEKDAY(TODAY(),3),"This week",IF(E14=TODAY()-WEEKDAY(TODAY(),3)+7,"Next week","")))) | G14: =IFERROR(INDEX(Grades!$G:$G,MATCH(A14,Grades!$A:$A,0)),"") -> Strong | H14: 46300 | J14: 46349 | K14: LTC | L14: RENDER | M14: 2
A15: ONDO | B15: yes | C15: =IF(B15="yes",13,26) -> 13 | D15: =IFERROR(INDEX(Grades!$X:$X,MATCH(A15,Grades!$A:$A,0)),"") -> 2026-10-05 | E15: 46342 | F15: =IF(E15="","",IF(E15<TODAY()-WEEKDAY(TODAY(),3),"Overdue",IF(E15=TODAY()-WEEKDAY(TODAY(),3),"This week",IF(E15=TODAY()-WEEKDAY(TODAY(),3)+7,"Next week","")))) | G15: =IFERROR(INDEX(Grades!$G:$G,MATCH(A15,Grades!$A:$A,0)),"") -> Average/Decent | H15: 46300 | J15: 46356 | K15: HYPE | L15: SAND | M15: 2
A16: TAO | B16: no | C16: =IF(B16="yes",13,26) -> 26 | D16: =IFERROR(INDEX(Grades!$X:$X,MATCH(A16,Grades!$A:$A,0)),"") -> 2026-10-05 | E16: 46335 | F16: =IF(E16="","",IF(E16<TODAY()-WEEKDAY(TODAY(),3),"Overdue",IF(E16=TODAY()-WEEKDAY(TODAY(),3),"This week",IF(E16=TODAY()-WEEKDAY(TODAY(),3)+7,"Next week","")))) | G16: =IFERROR(INDEX(Grades!$G:$G,MATCH(A16,Grades!$A:$A,0)),"") -> Average/Decent | H16: 46300 | J16: 46363 | K16: QNT | L16: XMR | M16: 2
A17: BNB | B17: no | C17: =IF(B17="yes",13,26) -> 26 | D17: =IFERROR(INDEX(Grades!$X:$X,MATCH(A17,Grades!$A:$A,0)),"") -> 2026-10-05 | E17: 46342 | F17: =IF(E17="","",IF(E17<TODAY()-WEEKDAY(TODAY(),3),"Overdue",IF(E17=TODAY()-WEEKDAY(TODAY(),3),"This week",IF(E17=TODAY()-WEEKDAY(TODAY(),3)+7,"Next week","")))) | G17: =IFERROR(INDEX(Grades!$G:$G,MATCH(A17,Grades!$A:$A,0)),"") -> Average/Decent | H17: 46300 | J17: 46370 | K17: PAXG | L17: ZEC | M17: 2
A18: RENDER | B18: no | C18: =IF(B18="yes",13,26) -> 26 | D18: =IFERROR(INDEX(Grades!$X:$X,MATCH(A18,Grades!$A:$A,0)),"") -> 2026-10-05 | E18: 46349 | F18: =IF(E18="","",IF(E18<TODAY()-WEEKDAY(TODAY(),3),"Overdue",IF(E18=TODAY()-WEEKDAY(TODAY(),3),"This week",IF(E18=TODAY()-WEEKDAY(TODAY(),3)+7,"Next week","")))) | G18: =IFERROR(INDEX(Grades!$G:$G,MATCH(A18,Grades!$A:$A,0)),"") -> Strong | H18: 46300 | J18: 46377 | K18: AVAX | L18: DOGE | M18: 2
A19: SAND | B19: no | C19: =IF(B19="yes",13,26) -> 26 | D19: =IFERROR(INDEX(Grades!$X:$X,MATCH(A19,Grades!$A:$A,0)),"") -> 2026-10-05 | E19: 46356 | F19: =IF(E19="","",IF(E19<TODAY()-WEEKDAY(TODAY(),3),"Overdue",IF(E19=TODAY()-WEEKDAY(TODAY(),3),"This week",IF(E19=TODAY()-WEEKDAY(TODAY(),3)+7,"Next week","")))) | G19: =IFERROR(INDEX(Grades!$G:$G,MATCH(A19,Grades!$A:$A,0)),"") -> Average/Decent | H19: 46300 | J19: 46384 | K19: HBAR | L19: SHIB | M19: 2
A20: XMR | B20: no | C20: =IF(B20="yes",13,26) -> 26 | D20: =IFERROR(INDEX(Grades!$X:$X,MATCH(A20,Grades!$A:$A,0)),"") -> 2026-10-05 | E20: 46363 | F20: =IF(E20="","",IF(E20<TODAY()-WEEKDAY(TODAY(),3),"Overdue",IF(E20=TODAY()-WEEKDAY(TODAY(),3),"This week",IF(E20=TODAY()-WEEKDAY(TODAY(),3)+7,"Next week","")))) | G20: =IFERROR(INDEX(Grades!$G:$G,MATCH(A20,Grades!$A:$A,0)),"") -> Strong | H20: 46300 | J20: 46391 | K20: XLM | L20: USDC | M20: 2
A21: ZEC | B21: no | C21: =IF(B21="yes",13,26) -> 26 | D21: =IFERROR(INDEX(Grades!$X:$X,MATCH(A21,Grades!$A:$A,0)),"") -> 2026-10-05 | E21: 46370 | F21: =IF(E21="","",IF(E21<TODAY()-WEEKDAY(TODAY(),3),"Overdue",IF(E21=TODAY()-WEEKDAY(TODAY(),3),"This week",IF(E21=TODAY()-WEEKDAY(TODAY(),3)+7,"Next week","")))) | G21: =IFERROR(INDEX(Grades!$G:$G,MATCH(A21,Grades!$A:$A,0)),"") -> Average/Decent | H21: 46300 | J21: 46398 | K21: BTC, ENA | M21: 2
A22: DOGE | B22: no | C22: =IF(B22="yes",13,26) -> 26 | D22: =IFERROR(INDEX(Grades!$X:$X,MATCH(A22,Grades!$A:$A,0)),"") -> 2026-10-05 | E22: 46377 | F22: =IF(E22="","",IF(E22<TODAY()-WEEKDAY(TODAY(),3),"Overdue",IF(E22=TODAY()-WEEKDAY(TODAY(),3),"This week",IF(E22=TODAY()-WEEKDAY(TODAY(),3)+7,"Next week","")))) | G22: =IFERROR(INDEX(Grades!$G:$G,MATCH(A22,Grades!$A:$A,0)),"") -> Average/Decent | H22: 46300 | J22: 46405 | K22: ETH | L22: USDT | M22: 2
A23: SHIB | B23: no | C23: =IF(B23="yes",13,26) -> 26 | D23: =IFERROR(INDEX(Grades!$X:$X,MATCH(A23,Grades!$A:$A,0)),"") -> 2026-10-05 | E23: 46384 | F23: =IF(E23="","",IF(E23<TODAY()-WEEKDAY(TODAY(),3),"Overdue",IF(E23=TODAY()-WEEKDAY(TODAY(),3),"This week",IF(E23=TODAY()-WEEKDAY(TODAY(),3)+7,"Next week","")))) | G23: =IFERROR(INDEX(Grades!$G:$G,MATCH(A23,Grades!$A:$A,0)),"") -> Average/Decent | H23: 46300 | J23: 46412 | K23: SOL | L23: IMX | M23: 2
A24: USDC | B24: no | C24: =IF(B24="yes",13,26) -> 26 | D24: =IFERROR(INDEX(Grades!$X:$X,MATCH(A24,Grades!$A:$A,0)),"") -> 2026-10-05 | E24: 46391 | F24: =IF(E24="","",IF(E24<TODAY()-WEEKDAY(TODAY(),3),"Overdue",IF(E24=TODAY()-WEEKDAY(TODAY(),3),"This week",IF(E24=TODAY()-WEEKDAY(TODAY(),3)+7,"Next week","")))) | G24: =IFERROR(INDEX(Grades!$G:$G,MATCH(A24,Grades!$A:$A,0)),"") -> Strong | H24: 46300 | J24: 46419 | K24: NEAR | L24: RED | M24: 2
A25: USDT | B25: no | C25: =IF(B25="yes",13,26) -> 26 | D25: =IFERROR(INDEX(Grades!$X:$X,MATCH(A25,Grades!$A:$A,0)),"") -> 2026-10-05 | E25: 46405 | F25: =IF(E25="","",IF(E25<TODAY()-WEEKDAY(TODAY(),3),"Overdue",IF(E25=TODAY()-WEEKDAY(TODAY(),3),"This week",IF(E25=TODAY()-WEEKDAY(TODAY(),3)+7,"Next week","")))) | G25: =IFERROR(INDEX(Grades!$G:$G,MATCH(A25,Grades!$A:$A,0)),"") -> Average/Decent | H25: 46300 | J25: 46426 | K25: LINK | L25: FET | M25: 2
A26: LTC | B26: yes | C26: =IF(B26="yes",13,26) -> 13 | D26: =IFERROR(INDEX(Grades!$X:$X,MATCH(A26,Grades!$A:$A,0)),"") -> 2026-10-05 | E26: 46349 | F26: =IF(E26="","",IF(E26<TODAY()-WEEKDAY(TODAY(),3),"Overdue",IF(E26=TODAY()-WEEKDAY(TODAY(),3),"This week",IF(E26=TODAY()-WEEKDAY(TODAY(),3)+7,"Next week","")))) | G26: =IFERROR(INDEX(Grades!$G:$G,MATCH(A26,Grades!$A:$A,0)),"") -> Strong | H26: 46300 | J26: 46433 | K26: ONDO | L26: RAY | M26: 2
A27: HYPE | B27: yes | C27: =IF(B27="yes",13,26) -> 13 | D27: =IFERROR(INDEX(Grades!$X:$X,MATCH(A27,Grades!$A:$A,0)),"") -> 2026-10-05 | E27: 46356 | F27: =IF(E27="","",IF(E27<TODAY()-WEEKDAY(TODAY(),3),"Overdue",IF(E27=TODAY()-WEEKDAY(TODAY(),3),"This week",IF(E27=TODAY()-WEEKDAY(TODAY(),3)+7,"Next week","")))) | G27: =IFERROR(INDEX(Grades!$G:$G,MATCH(A27,Grades!$A:$A,0)),"") -> Average/Decent | H27: 46300 | J27: 46440 | K27: LTC | L27: NIGHT | M27: 2
A28: QNT | B28: yes | C28: =IF(B28="yes",13,26) -> 13 | D28: =IFERROR(INDEX(Grades!$X:$X,MATCH(A28,Grades!$A:$A,0)),"") -> 2026-10-05 | E28: 46363 | F28: =IF(E28="","",IF(E28<TODAY()-WEEKDAY(TODAY(),3),"Overdue",IF(E28=TODAY()-WEEKDAY(TODAY(),3),"This week",IF(E28=TODAY()-WEEKDAY(TODAY(),3)+7,"Next week","")))) | G28: =IFERROR(INDEX(Grades!$G:$G,MATCH(A28,Grades!$A:$A,0)),"") -> Strong | H28: 46300 | J28: 46447 | K28: HYPE | L28: POWR | M28: 2
A29: IMX | B29: no | C29: =IF(B29="yes",13,26) -> 26 | D29: =IFERROR(INDEX(Grades!$X:$X,MATCH(A29,Grades!$A:$A,0)),"") -> 2026-10-05 | E29: 46412 | F29: =IF(E29="","",IF(E29<TODAY()-WEEKDAY(TODAY(),3),"Overdue",IF(E29=TODAY()-WEEKDAY(TODAY(),3),"This week",IF(E29=TODAY()-WEEKDAY(TODAY(),3)+7,"Next week","")))) | G29: =IFERROR(INDEX(Grades!$G:$G,MATCH(A29,Grades!$A:$A,0)),"") -> Weak | H29: 46300 | J29: 46454 | K29: QNT | L29: PEPE | M29: 2
A30: PAXG | B30: yes | C30: =IF(B30="yes",13,26) -> 13 | D30: =IFERROR(INDEX(Grades!$X:$X,MATCH(A30,Grades!$A:$A,0)),"") -> 2026-10-05 | E30: 46370 | F30: =IF(E30="","",IF(E30<TODAY()-WEEKDAY(TODAY(),3),"Overdue",IF(E30=TODAY()-WEEKDAY(TODAY(),3),"This week",IF(E30=TODAY()-WEEKDAY(TODAY(),3)+7,"Next week","")))) | G30: =IFERROR(INDEX(Grades!$G:$G,MATCH(A30,Grades!$A:$A,0)),"") -> Strong | H30: 46300 | J30: 46461 | K30: PAXG | L30: CRO | M30: 2
A31: RED | B31: no | C31: =IF(B31="yes",13,26) -> 26 | D31: =IFERROR(INDEX(Grades!$X:$X,MATCH(A31,Grades!$A:$A,0)),"") -> 2026-10-05 | E31: 46419 | F31: =IF(E31="","",IF(E31<TODAY()-WEEKDAY(TODAY(),3),"Overdue",IF(E31=TODAY()-WEEKDAY(TODAY(),3),"This week",IF(E31=TODAY()-WEEKDAY(TODAY(),3)+7,"Next week","")))) | G31: =IFERROR(INDEX(Grades!$G:$G,MATCH(A31,Grades!$A:$A,0)),"") -> Weak | H31: 46300 | J31: 46468 | K31: AVAX | L31: CAKE | M31: 2
A32: FET | B32: no | C32: =IF(B32="yes",13,26) -> 26 | D32: =IFERROR(INDEX(Grades!$X:$X,MATCH(A32,Grades!$A:$A,0)),"") -> 2026-10-05 | E32: 46426 | F32: =IF(E32="","",IF(E32<TODAY()-WEEKDAY(TODAY(),3),"Overdue",IF(E32=TODAY()-WEEKDAY(TODAY(),3),"This week",IF(E32=TODAY()-WEEKDAY(TODAY(),3)+7,"Next week","")))) | G32: =IFERROR(INDEX(Grades!$G:$G,MATCH(A32,Grades!$A:$A,0)),"") -> Average/Decent | H32: 46300 | J32: 46475 | K32: HBAR | L32: SKY | M32: 2
A33: RAY | B33: no | C33: =IF(B33="yes",13,26) -> 26 | D33: =IFERROR(INDEX(Grades!$X:$X,MATCH(A33,Grades!$A:$A,0)),"") -> 2026-10-05 | E33: 46433 | F33: =IF(E33="","",IF(E33<TODAY()-WEEKDAY(TODAY(),3),"Overdue",IF(E33=TODAY()-WEEKDAY(TODAY(),3),"This week",IF(E33=TODAY()-WEEKDAY(TODAY(),3)+7,"Next week","")))) | G33: =IFERROR(INDEX(Grades!$G:$G,MATCH(A33,Grades!$A:$A,0)),"") -> Weak | H33: 46300 | J33: 46482 | K33: XLM | L33: GRASS | M33: 2
A34: NIGHT | B34: no | C34: =IF(B34="yes",13,26) -> 26 | D34: =IFERROR(INDEX(Grades!$X:$X,MATCH(A34,Grades!$A:$A,0)),"") -> 2026-10-05 | E34: 46440 | F34: =IF(E34="","",IF(E34<TODAY()-WEEKDAY(TODAY(),3),"Overdue",IF(E34=TODAY()-WEEKDAY(TODAY(),3),"This week",IF(E34=TODAY()-WEEKDAY(TODAY(),3)+7,"Next week","")))) | G34: =IFERROR(INDEX(Grades!$G:$G,MATCH(A34,Grades!$A:$A,0)),"") -> Average/Decent | H34: 46300 | J34: 46489 | K34: BTC, ENA | M34: 2
